2018-03-18 07:58:12,517 INFO: Tracer startup [in /home/pi/tracer1210/solar-rest.py:29]
2018-03-18 08:12:44,268 INFO: Tracer startup [in /home/pi/tracer1210/solar-rest.py:29]
2018-03-18 08:13:28,601 ERROR: Exception on /load_off [GET] [in /home/pi/tracer1210/venv/lib/python3.5/site-packages/flask/app.py:1560]
Traceback (most recent call last):
  File "/home/pi/tracer1210/venv/lib/python3.5/site-packages/flask/app.py", line 1982, in wsgi_app
    response = self.full_dispatch_request()
  File "/home/pi/tracer1210/venv/lib/python3.5/site-packages/flask/app.py", line 1614, in full_dispatch_request
    rv = self.handle_user_exception(e)
  File "/home/pi/tracer1210/venv/lib/python3.5/site-packages/flask/app.py", line 1517, in handle_user_exception
    reraise(exc_type, exc_value, tb)
  File "/home/pi/tracer1210/venv/lib/python3.5/site-packages/flask/_compat.py", line 33, in reraise
    raise value
  File "/home/pi/tracer1210/venv/lib/python3.5/site-packages/flask/app.py", line 1612, in full_dispatch_request
    rv = self.dispatch_request()
  File "/home/pi/tracer1210/venv/lib/python3.5/site-packages/flask/app.py", line 1598, in dispatch_request
    return self.view_functions[rule.endpoint](**req.view_args)
  File "/home/pi/tracer1210/solar-rest.py", line 112, in load_off
    data = t_ser.receive_result()
  File "/home/pi/tracer1210/tracer.py", line 130, in receive_result
    return self.from_bytes(buff)
  File "/home/pi/tracer1210/tracer.py", line 87, in from_bytes
    raise Exception("Invalid sync header")
Exception: Invalid sync header
2018-03-18 09:38:38,290 ERROR: Exception on /load_off [GET] [in /home/pi/tracer1210/venv/lib/python3.5/site-packages/flask/app.py:1560]
Traceback (most recent call last):
  File "/home/pi/tracer1210/venv/lib/python3.5/site-packages/flask/app.py", line 1982, in wsgi_app
    response = self.full_dispatch_request()
  File "/home/pi/tracer1210/venv/lib/python3.5/site-packages/flask/app.py", line 1614, in full_dispatch_request
    rv = self.handle_user_exception(e)
  File "/home/pi/tracer1210/venv/lib/python3.5/site-packages/flask/app.py", line 1517, in handle_user_exception
    reraise(exc_type, exc_value, tb)
  File "/home/pi/tracer1210/venv/lib/python3.5/site-packages/flask/_compat.py", line 33, in reraise
    raise value
  File "/home/pi/tracer1210/venv/lib/python3.5/site-packages/flask/app.py", line 1612, in full_dispatch_request
    rv = self.dispatch_request()
  File "/home/pi/tracer1210/venv/lib/python3.5/site-packages/flask/app.py", line 1598, in dispatch_request
    return self.view_functions[rule.endpoint](**req.view_args)
  File "/home/pi/tracer1210/solar-rest.py", line 112, in load_off
    data = t_ser.receive_result()
  File "/home/pi/tracer1210/tracer.py", line 130, in receive_result
    return self.from_bytes(buff)
  File "/home/pi/tracer1210/tracer.py", line 87, in from_bytes
    raise Exception("Invalid sync header")
Exception: Invalid sync header
2018-03-18 13:15:29,261 INFO: Tracer startup [in /home/pi/tracer1210/solar-rest.py:33]
2018-03-18 18:28:53,684 INFO: Tracer startup [in /home/pi/tracer1210/solar_rest.py:33]
2018-03-18 18:29:17,325 INFO: Tracer startup [in /home/pi/tracer1210/solar_rest.py:33]
2018-03-18 18:29:31,670 ERROR: Exception on /solar [GET] [in /home/pi/tracer1210/venv/lib/python3.5/site-packages/flask/app.py:1560]
Traceback (most recent call last):
  File "/home/pi/tracer1210/venv/lib/python3.5/site-packages/flask/app.py", line 1982, in wsgi_app
    response = self.full_dispatch_request()
  File "/home/pi/tracer1210/venv/lib/python3.5/site-packages/flask/app.py", line 1614, in full_dispatch_request
    rv = self.handle_user_exception(e)
  File "/home/pi/tracer1210/venv/lib/python3.5/site-packages/flask/app.py", line 1517, in handle_user_exception
    reraise(exc_type, exc_value, tb)
  File "/home/pi/tracer1210/venv/lib/python3.5/site-packages/flask/_compat.py", line 33, in reraise
    raise value
  File "/home/pi/tracer1210/venv/lib/python3.5/site-packages/flask/app.py", line 1612, in full_dispatch_request
    rv = self.dispatch_request()
  File "/home/pi/tracer1210/venv/lib/python3.5/site-packages/flask/app.py", line 1598, in dispatch_request
    return self.view_functions[rule.endpoint](**req.view_args)
  File "/home/pi/tracer1210/solar_rest.py", line 51, in get_data
    data = t_ser.receive_result()
  File "/home/pi/tracer1210/tracer.py", line 130, in receive_result
    return self.from_bytes(buff)
  File "/home/pi/tracer1210/tracer.py", line 87, in from_bytes
    raise Exception("Invalid sync header")
Exception: Invalid sync header
